Workbook

Sheet Caratula
A1: Junio - 2026
A4: º
A26: *Observación: En base a los datos del sistema SOFIA proveído por la Dirección Nacional de Aduanas.
A27: Uso exclusivo de las empresas asociadas de CADAM
A28: Elaborado por el departamento de estadística - CADAM

Sheet Indice
A1: =UPPER("Cuadro") -> CUADRO | B1: DESCRIPCIÓN | C1: PÁGINA
A2: Cuadro 1 | B2: Parque Automotor : vehículos y camiones 0km, mensual 2014 y anual 1998-2026 | C2: 1
A3: Cuadro 2 | B3: Importación de vehículos por tipo,variacion 2022-2026 | C3: 2
A4: Cuadro 3 | B4: Importación de vehículos por tipo y mes, 2026 | C4: 3
A5: Cuadro 4 | B5: Importación de vehículos variación mensual, 2025-2026 | C5: 4
A6: Cuadro 5 | B6: Importación de vehículos por marca y mes, 2026 | C6: 5
A7: Cuadro 6 | B7: Importación de vehículos por pais de procedencia y mes, 2026 | C7: 6
A8: Cuadro 7 | B8: Importación de vehículos por Marca y empresa, 2026 | C8: 7
A9: Cuadro 8 | B9: Importación de vehículos por modelo, por mes y valor Cif U$S de importación, 2026 | C9: 8
A10: Cuadro 9 | B10: Importación de vehículos por tipo, 2026 | C10: 9
A11: Cuadro 10 | B11: Importaciones por tipos de vehículos y tipos de combustibles, por mes, 2026 | C11: 10
A12: Cuadro 11 | B12: Importación de vehículos por tipo y mes. Serie 2008-2026 | C12: 11
A13: Cuadro 12 | B13: Importación de vehículos 0km y usados por año, 1998-2026 | C13: 12
... A30: Cuadro 29 | B30: Importación de vehículos 0Km por marca 2003-2024 | C30: 29

Sheet Resumen
A1: Valor CIF de importaciones de automotores, en millones de U$S, por año, 2010-2025 | U1: Valor CIF de importación de automotores, en millones de U$S. 2025- 2026
A2: Total | B2: 2010 | C2: 2011 | D2: 2012 | E2: 2013 | F2: 2014 | G2: 2015 | H2: 2016 | I2: 2017 | J2: 2018 | K2: 2019 | L2: 2020 | M2: 2021 | N2: 2022 | O2: 2023 | P2: 2024 | Q2: 2025 | R2: Var.% 2025/2024 | U2: Total | V2: Jun 2025 | W2: Jun 2026 | X2: Var. %
A3: Vehículos 0km | B3: 315.699 | C3: 470.889 | D3: 486.904 | E3: 478.969 | F3: 530.901 | G3: 448 | H3: 382.577 | I3: 493.28079 | J3: 621.22749 | K3: 467.39855 | L3: 361.98061 | M3: 490.10006 | N3: 628.17492 | O3: 620.92963 | P3: 747.42954 | Q3: 750.46409 | R3: =+Q3/P3-1 -> 0.0040599791 | U3: Vehículos 0km | V3: 352.22159 | W3: 492.43829 | X3: =+W3/V3-1 -> 0.39809228 | Z3: =+Y3/1000000 -> 0
A4: Camiones 0km | B4: 49.845 | C4: 56.693 | D4: 63.913 | E4: 56.581 | F4: 55.937 | G4: 98.9 | H4: 61.22 | I4: 66.73418 | J4: 66.73418 | K4: 58.353199 | L4: 36.112935 | M4: 45.208219 | N4: 43.467873 | O4: 56.169802 | P4: 57.089428 | Q4: 77.838796 | R4: =+Q4/P4-1 -> 0.36345377 | U4: Camiones 0km | V4: 34.367659 | W4: 35.561022 | X4: =+W4/V4-1 -> 0.034723437 | Z4: =+Y4/1000000 -> 0
A5: Tractores | B5: 67.092 | C5: 111.452 | D5: 49.084 | R5: =+D5/C5-1 -> -0.55959516 | U5: Tractores | X5: =+W5/V5-1 -> #DIV/0!
A6: Cosechadoras | B6: 52.196 | C6: 108.802 | D6: 42.098 | R6: =+D6/C6-1 -> -0.61307697 | U6: Cosechadoras | X6: =+W6/V6-1 -> #DIV/0!
A7: Pulverizadoras | B7: 7.885 | C7: 46.227 | D7: 16.101 | R7: =+D7/C7-1 -> -0.65169706 | U7: Pulverizadoras | X7: =+W7/V7-1 -> #DIV/0!
A8: Maq. Viales e industriales | B8: 24.5775 | C8: 39.0646 | D8: 39.037 | R8: =+D8/C8-1 -> -0.00070652202 | U8: Maq. Viales e industriales | X8: =+W8/V8-1 -> #DIV/0!
A9: Total | B9: =SUM(B3:B8) -> 517.2945 | C9: =SUM(C3:C8) -> 833.1276 | D9: =SUM(D3:D8) -> 697.137 | E9: =SUM(E3:E8) -> 535.55 | F9: =SUM(F3:F8) -> 586.838 | G9: =SUM(G3:G8) -> 546.9 | H9: =SUM(H3:H8) -> 443.797 | I9: =SUM(I3:I8) -> 560.01497 | ... O9: =SUM(O3:O8) -> 677.09944 | P9: =SUM(P3:P4) -> 804.51897 | Q9: =SUM(Q3:Q4) -> 828.30288 | R9: =+Q9/P9-1 -> 0.029562903 | U9: Total | V9: =SUM(V3:V8) -> 386.58925 | W9: =SUM(W3:W8) -> 527.99931 | X9: =+W9/V9-1 -> 0.36578891
A10: Elaboracion: CADAM. Fuente: Penta Transaction. | U10: Elaboracion: CADAM. Fuente: Penta Transaction.
A12: Importación de automotores, en unidades, por año, 2010-2025 | U12: Importación de automotores, en unidades, 2025-2026
A13: Total | B13: 2010 | C13: 2011 | D13: 2012 | E13: 2013 | F13: 2014 | G13: 2015 | H13: 2016 | I13: 2017 | J13: 2018 | K13: 2019 | L13: 2020 | M13: 2021 | N13: 2022 | O13: 2023 | P13: 2024 | Q13: 2025 | R13: Var.% 2025/2024 | U13: Total | V13: Jun 2025 | W13: Jun 2026 | X13: Var. %
A14: Vehículos 0km | B14: 20215 | C14: 29392 | D14: 28887 | E14: 28190 | F14: 30691 | G14: 24559 | H14: 20802 | I14: 27851 | J14: 35890 | K14: 28437 | L14: 22000 | M14: 27910 | N14: 34185 | O14: 29720 | P14: 34705 | Q14: 38611 | R14: =+Q14/P14-1 -> 0.11254862 | U14: Vehículos 0km | V14: 16850 | W14: 24047 | X14: =+W14/V14-1 -> 0.42712166
A15: Camiones 0km | B15: 1814 | C15: 2415 | D15: 2715 | E15: 2930 | F15: 3470 | G15: 3786 | H15: 2017 | I15: 2510 | J15: 2509 | K15: 2298 | L15: 1479 | M15: 1821 | N15: 1563 | O15: 1677 | P15: 2013 | Q15: 2341 | R15: =+Q15/P15-1 -> 0.16294088 | U15: Camiones 0km | V15: 939 | W15: 1298 | X15: =+W15/V15-1 -> 0.38232162
A16: Tractores | B16: 1854 | C16: 2963 | D16: 1235 | R16: =+J16/H16-1 -> #DIV/0! | U16: Tractores | X16: =+W16/V16-1 -> #DIV/0!
A17: Cosechadoras | B17: 435 | C17: 720 | D17: 420 | R17: =+J17/H17-1 -> #DIV/0! | U17: Cosechadoras | X17: =+W17/V17-1 -> #DIV/0!
A18: Pulverizadoras | B18: 131 | C18: 371 | D18: 119 | R18: =+J18/H18-1 -> #DIV/0! | U18: Pulverizadoras | X18: =+W18/V18-1 -> #DIV/0!
A19: Maq. Viales e industriales | B19: 312 | C19: 802 | D19: 676 | R19: =+J19/H19-1 -> #DIV/0! | U19: Maq. Viales e industriales | X19: =+W19/V19-1 -> #DIV/0!
A20: Total Vehiculos y Camiones | B20: =+B14+B15 -> 22029 | C20: =+C14+C15 -> 31807 | D20: =+D14+D15 -> 31602 | E20: =SUM(E14:E19) -> 31120 | F20: =SUM(F14:F19) -> 34161 | G20: =SUM(G14:G19) -> 28345 | H20: =SUM(H14:H19) -> 22819 | I20: =+I14+I15 -> 30361 | J20: =+J14+J15 -> 38399 | K20: =SUM(K14:K19) -> 30735 | L20: =SUM(L14:L19) -> 23479 | M20: =SUM(M14:M19) -> 29731 | N20: =SUM(N14:N19) -> 35748 | O20: =SUM(O14:O19) -> 31397 | P20: =SUM(P14:P15) -> 36718 | Q20: =SUM(Q14:Q15) -> 40952 | R20: =+Q20/P20-1 -> 0.11531129 | U20: Total | V20: =SUM(V14:V19) -> 17789 | W20: =SUM(W14:W19) -> 25345 | X20: =+W20/V20-1 -> 0.42475687
A21: Elaboracion: CADAM. Fuente: DNA | U21: Elaboración: CADAM. Fuente: DNA

Sheet 1
A1: Parque Automotor : vehículos y camiones 0km, mensual 2020 y anual 1998-2026
A3: Cuadro 1: Importaciones de automoviles y camiones 0km, mensual 2026
A4: Año | B4: Vehículos | C4: Var % | D4: Camiones | E4: Var % | F4: Total | G4: Var %
A5: Enero | B5: 3205 | D5: 182 | F5: =+B5+D5 -> 3387
A6: Febrero | B6: 3319 | C6: =+B6/B5-1 -> 0.035569423 | D6: 198 | E6: =+D6/D5-1 -> 0.087912088 | F6: =+B6+D6 -> 3517 | G6: =+F6/F5-1 -> 0.038382049
A7: Marzo | B7: 4038 | C7: =+B7/B6-1 -> 0.21663152 | D7: 214 | E7: =+D7/D6-1 -> 0.080808081 | F7: =+B7+D7 -> 4252 | G7: =+F7/F6-1 -> 0.20898493
A8: Abril | B8: 4624 | C8: =+B8/B7-1 -> 0.14512135 | D8: 290 | E8: =+D8/D7-1 -> 0.35514019 | F8: =+B8+D8 -> 4914 | G8: =+F8/F7-1 -> 0.15569144
A9: Mayo | B9: 4341 | C9: =+B9/B8-1 -> -0.061202422 | D9: 206 | E9: =+D9/D8-1 -> -0.28965517 | F9: =+B9+D9 -> 4547 | G9: =+F9/F8-1 -> -0.074684575
A10: Junio | B10: 4520 | C10: =+B10/B9-1 -> 0.041234739 | D10: 208 | E10: =+D10/D9-1 -> 0.0097087379 | F10: =+B10+D10 -> 4728 | G10: =+F10/F9-1 -> 0.039806466
A11: Julio | C11: =+B11/B10-1 -> -1 | E11: =+D11/D10-1 -> -1 | F11: =+B11+D11 -> 0 | G11: =+F11/F10-1 -> -1
A12: Agosto | C12: =+B12/B11-1 -> #DIV/0! | E12: =+D12/D11-1 -> #DIV/0! | F12: =+B12+D12 -> 0 | G12: =+F12/F11-1 -> #DIV/0!
A13: Septiembre | C13: =+B13/B12-1 -> #DIV/0! | E13: =+D13/D12-1 -> #DIV/0! | F13: =+B13+D13 -> 0 | G13: =+F13/F12-1 -> #DIV/0!
A14: Octubre | C14: =+B14/B13-1 -> #DIV/0! | E14: =+D14/D13-1 -> #DIV/0! | F14: =+B14+D14 -> 0 | G14: =+F14/F13-1 -> #DIV/0!
A15: Noviembre | C15: =+B15/B14-1 -> #DIV/0! | E15: =+D15/D14-1 -> #DIV/0! | F15: =+B15+D15 -> 0 | G15: =+F15/F14-1 -> #DIV/0!
A16: Diciembre | C16: =+B16/B15-1 -> #DIV/0! | E16: =+D16/D15-1 -> #DIV/0! | F16: =+B16+D16 -> 0 | G16: =+F16/F15-1 -> #DIV/0!
A17: Total | B17: =SUM(B5:B16) -> 24047 | D17: =SUM(D5:D16) -> 1298 | F17: =SUM(F5:F16) -> 25345
A18: Fuente: CADAM
A20: Cuadro 1A:Importaciones de vehículos y camiones 0km, 1998-2026
A21: Año | B21: Vehículos | C21: Var % | D21: Camiones | E21: Var % | F21: Total | G21: Var %
A23: 1998 | B23: 15259 | D23: 1152 | F23: =+B23+D23 -> 16411
A24: 1999 | B24: 9666 | C24: =+B24/B23-1 -> -0.36653778 | D24: 887 | E24: =+D24/D23-1 -> -0.23003472 | F24: =+B24+D24 -> 10553 | G24: =+F24/F23-1 -> -0.3569557
A25: 2000 | B25: 6780 | C25: =+B25/B24-1 -> -0.29857232 | D25: 524 | E25: =+D25/D24-1 -> -0.40924464 | F25: =+B25+D25 -> 7304 | G25: =+F25/F24-1 -> -0.30787454
A26: 2001 | B26: 6559 | C26: =+B26/B25-1 -> -0.03259587 | D26: 427 | E26: =+D26/D25-1 -> -0.1851145 | F26: =+B26+D26 -> 6986 | G26: =+F26/F25-1 -> -0.043537788
A27: 2002 | B27: 2842 | C27: =+B27/B26-1 -> -0.56670224 | D27: 192 | E27: =+D27/D26-1 -> -0.55035129 | F27: =+B27+D27 -> 3034 | G27: =+F27/F26-1 -> -0.56570283
A28: 2003 | B28: 3209 | C28: =+B28/B27-1 -> 0.12913441 | D28: 53 | E28: =+D28/D27-1 -> -0.72395833 | F28: =+B28+D28 -> 3262 | G28: =+F28/F27-1 -> 0.075148319
A29: 2004 | B29: 5720 | C29: =+B29/B28-1 -> 0.78248676 | D29: 234 | E29: =+D29/D28-1 -> 3.4150943 | F29: =+B29+D29 -> 5954 | G29: =+F29/F28-1 -> 0.82526058
A30: 2005 | B30: 6710 | C30: =+B30/B29-1 -> 0.17307692 | D30: 399 | E30: =+D30/D29-1 -> 0.70512821 | F30: =+B30+D30 -> 7109 | G30: =+F30/F29-1 -> 0.19398724
A31: 2006 | B31: 8417 | C31: =+B31/B30-1 -> 0.25439642 | D31: 566 | E31: =+D31/D30-1 -> 0.41854637 | F31: =+B31+D31 -> 8983 | G31: =+F31/F30-1 -> 0.26360951
A32: 2007 | B32: 11898 | C32: =+B32/B31-1 -> 0.41356778 | D32: 1007 | E32: =+D32/D31-1 -> 0.77915194 | F32: =+B32+D32 -> 12905 | G32: =+F32/F31-1 -> 0.43660247
A33: 2008 | B33: 20266 | C33: =+B33/B32-1 -> 0.70331148 | D33: 2048 | E33: =+D33/D32-1 -> 1.0337637 | F33: =+B33+D33 -> 22314 | G33: =+F33/F32-1 -> 0.72909725
A34: 2009 | B34: 12160 | C34: =+B34/B33-1 -> -0.39998026 | D34: 1570 | E34: =+D34/D33-1 -> -0.23339844 | F34: =+B34+D34 -> 13730 | G34: =+F34/F33-1 -> -0.38469123
A35: 2010 | B35: 20215 | C35: =+B35/B34-1 -> 0.66241776 | D35: 1814 | E35: =+D35/D34-1 -> 0.15541401 | F35: =+B35+D35 -> 22029 | G35: =+F35/F34-1 -> 0.60444283
... A43: 2018 | B43: 35890 | C43: =+B43/B42-1 -> 0.28864314 | D43: 2509 | E43: =+D43/D42-1 -> -0.00039840637 | F43: =+B43+D43 -> 38399 | G43: =+F43/F42-1 -> 0.26474754
A44: 2019 | B44: 28437 | C44: =+B44/B43-1 -> -0.2076623 | D44: 2298 | E44: -0.08409725 | F44: 30735 | G44: =+F44/F43-1 -> -0.19958853
A45: 2020 | B45: 22000 | C45: =+B45/B44-1 -> -0.22636002 | D45: 1479 | E45: =+D45/D44-1 -> -0.35639687 | F45: =+B45+D45 -> 23479 | G45: =+F45/F44-1 -> -0.23608264
A46: 2021 | B46: 27910 | C46: =+B46/B45-1 -> 0.26863636 | D46: 1821 | E46: =+D46/D45-1 -> 0.23123732 | F46: =+B46+D46 -> 29731 | G46: =+F46/F45-1 -> 0.26628051
A47: 2022 | B47: 34185 | C47: =+B47/B46-1 -> 0.22482981 | D47: 1563 | E47: =+D47/D46-1 -> -0.1416804 | F47: =+B47+D47 -> 35748 | G47: =+F47/F46-1 -> 0.20238135
A48: 2023 | B48: 29720 | C48: =+B48/B47-1 -> -0.13061284 | D48: 1677 | E48: =+D48/D47-1 -> 0.07293666 | F48: =+B48+D48 -> 31397 | G48: =+F48/F47-1 -> -0.1217131
A49: 2024 | B49: 34705 | C49: =+B49/B48-1 -> 0.16773217 | D49: 2013 | E49: =+D49/D48-1 -> 0.20035778 | F49: =+B49+D49 -> 36718 | G49: =+F49/F48-1 -> 0.16947479
A50: 2025 | B50: 38611 | C50: =+B50/B49-1 -> 0.11254862 | D50: 2341 | E50: =+D50/D49-1 -> 0.16294088 | F50: =+B50+D50 -> 40952 | G50: =+F50/F49-1 -> 0.11531129
...

Sheet 2
A1: Cuadro 2: Importación de automotores por tipo,variacion 2025 - 2026
A2: Tipo | B2: 46143 | C2: 46174 | D2: Var % | E2: 45809 | F2: 46174 | G2: Var % | H2: Acum 2025 | I2: Acum 2026 | J2: Acum Var % | K2: En %
B3: (a) | C3: ( b) | D3: (b)/(a) | E3: ('c) | F3: ( d) | G3: (d)/('c) | H3: (e) | I3: (f) | J3: (f)/('e) | K3: Junio
A4: Automóvil | B4: 555 | C4: 744 | D4: =+C4/B4-1 -> 0.34054054 | E4: 492 | F4: 744 | G4: =+F4/E4-1 -> 0.51219512 | H4: 2977 | I4: 2980 | J4: =+I4/H4-1 -> 0.0010077259 | K4: =+I4/I9 -> 0.12392398
A5: Furgón | B5: 31 | C5: 121 | D5: =+C5/B5-1 -> 2.9032258 | E5: 141 | F5: 121 | G5: =+F5/E5-1 -> -0.14184397 | H5: 388 | I5: 426 | J5: =+I5/H5-1 -> 0.097938144 | K5: =+I5/I9 -> 0.017715308
A6: Minibus | B6: 10 | C6: 10 | D6: =+C6/B6-1 -> 0 | E6: 13 | F6: 10 | G6: =+F6/E6-1 -> -0.23076923 | H6: 196 | I6: 141 | J6: =+I6/H6-1 -> -0.28061224 | K6: =+I6/I9 -> 0.0058635173
A7: Pick Up | B7: 1157 | C7: 733 | D7: =+C7/B7-1 -> -0.366465 | E7: 740 | F7: 733 | G7: =+F7/E7-1 -> -0.0094594595 | H7: 3792 | I7: 5315 | J7: =+I7/H7-1 -> 0.40163502 | K7: =+I7/I9 -> 0.22102549
A8: SUV | B8: 2588 | C8: 2912 | D8: =+C8/B8-1 -> 0.1251932 | E8: 1968 | F8: 2912 | G8: =+F8/E8-1 -> 0.4796748 | H8: 9497 | I8: 15185 | J8: =+I8/H8-1 -> 0.59892598 | K8: =+I8/I9 -> 0.6314717
A9: Total vehículos | B9: =SUM(B4:B8) -> 4341 | C9: =SUM(C4:C8) -> 4520 | D9: =+C9/B9-1 -> 0.041234739 | E9: =SUM(E4:E8) -> 3354 | F9: =SUM(F4:F8) -> 4520 | G9: =+F9/E9-1 -> 0.3476446 | H9: =SUM(H4:H8) -> 16850 | I9: =SUM(I4:I8) -> 24047 | J9: =+I9/H9-1 -> 0.42712166 | K9: =+I9/I9 -> 1
A10: Camión | B10: 169 | C10: 198 | D10: =+C10/B10-1 -> 0.17159763 | E10: 140 | F10: 198 | G10: =+F10/E10-1 -> 0.41428571 | H10: 882 | I10: 1226 | J10: =+I10/H10-1 -> 0.39002268 | K10: =+I10/I12 -> 0.94453005
A11: Omnibus | B11: 37 | C11: 10 | D11: =+C11/B11-1 -> -0.72972973 | E11: 3 | F11: 10 | G11: =+F11/E11-1 -> 2.3333333 | H11: 57 | I11: 72 | J11: =+I11/H11-1 -> 0.26315789 | K11: =+I11/I12 -> 0.055469954
A12: Total camiones | B12: =SUM(B10:B11) -> 206 | C12: =SUM(C10:C11) -> 208 | D12: =+C12/B12-1 -> 0.0097087379 | E12: =SUM(E10:E11) -> 143 | F12: =+F10+F11 -> 208 | G12: =+F12/E12-1 -> 0.45454545 | H12: =SUM(H10:H11) -> 939 | I12: =SUM(I10:I11) -> 1298 | J12: =+I12/H12-1 -> 0.38232162 | K12: =+I12/I12 -> 1
A13: Fuente: CADAM

Sheet 3
A1: Cuadro 3: Importación de vehículos por tipo y mes, 2026 | Q1: Cuadro 3 A: Importación de vehículos por tipo, 2011- 2026
A2: Tipo de vehículos | B2: Ene | C2: Feb | D2: Mar | E2: Abr | F2: May | G2: Jun | H2: Jul | I2: Ago | J2: Sep | K2: Oct | L2: Nov | M2: Dic | N2: Total | O2: % | Q2: Tipo de vehículos | R2: 2011 | T2: 2012 | V2: 2013 | X2: 2014 | Z2: 2015 | AB2: 2016 | AD2: 2017 | AF2: 2018 | AH2: 2019 | AJ2: 2020 | AL2: 2021 | AN2: 2022 | AP2: 2023 | AR2: 2024 | AT2: 2025 | AV2: 2026
A3: Automóvil | B3: 437 | C3: 371 | D3: 419 | E3: 454 | F3: 555 | G3: 744 | N3: =SUM(B3:M3) -> 2980 | O3: =+N3/$N$8 -> 0.12392398 | R3: Unidades | S3: En % | T3: Unidades | U3: En % | V3: Unidades | W3: En % | X3: Unidades | Y3: En % | Z3: Unidades | AA3: En % | AB3: Unidades | AC3: En % | AD3: Unidades | AE3: En % | AF3: Unidades | AG3: En % | AH3: Unidades | AI3: En % | AJ3: Unidades | AK3: En % | AL3: Unidades | AM3: En % | AN3: Unidades | AO3: En % | AP3: Unidades | AQ3: En % | AR3: Unidades | AS3: En % | AT3: Unidades | AU3: En % | AV3: Unidades | AW3: En %
A4: Furgón | B4: 63 | C4: 48 | D4: 34 | E4: 129 | F4: 31 | G4: 121 | N4: =SUM(B4:M4) -> 426 | O4: =+N4/$N$8 -> 0.017715308 | Q4: Automóvil | R4: 11732 | S4: =+R4/$R$9 -> 0.39915623 | T4: 10977 | U4: =+T4/$T$9 -> 0.37999792 | V4: 12740 | W4: =+V4/$V$9 -> 0.45193331 | X4: 13747 | Y4: =+X4/X9 -> 0.44791633 | Z4: 9108 | AA4: =+Z4/Z9 -> 0.37086201 | AB4: 8053 | AC4: =+AB4/AB9 -> 0.38712624 | AD4: 10886 | AE4: =+AD4/AD9 -> 0.39086568 | AF4: 15256 | AG4: =+AF4/$AF$9 -> 0.42507662 | AH4: 12974 | AI4: 0.45623659 | AJ4: 10827 | AK4: =+AJ4/AJ9 -> 0.49213636 | AL4: 10890 | AM4: =+AL4/AL9 -> 0.39018273 | AN4: 9379 | AO4: =+AN4/$AN$9 -> 0.2743601 | AP4: 6056 | AQ4: =+AP4/$AP$9 -> 0.20376851 | AR4: 6059 | AS4: =+AR4/$AR$9 -> 0.17458579 | AT4: 5134 | AU4: =+AT4/$AT$9 -> 0.16370651 | AV4: =+N3 -> 2980 | AW4: =+AV4/AV9 -> 0.12392398
A5: Minibus | B5: 46 | C5: 26 | D5: 35 | E5: 14 | F5: 10 | G5: 10 | N5: =SUM(B5:M5) -> 141 | O5: =+N5/$N$8 -> 0.0058635173 | Q5: Furgón | R5: 668 | S5: =+R5/$R$9 -> 0.022727273 | T5: 681 | U5: =+T5/$T$9 -> 0.023574618 | V5: 670 | W5: =+V5/$V$9 -> 0.023767293 | X5: 389 | Y5: =+X5/X9 -> 0.012674725 | Z5: 587 | AA5: =+Z5/Z9 -> 0.023901625 | AB5: 215 | AC5: =+AB5/AB9 -> 0.010335545 | AD5: 388 | AE5: =+AD5/AD9 -> 0.013931277 | AF5: 368 | AG5: =+AF5/$AF$9 -> 0.010253553 | AH5: 411 | AI5: 0.014453001 | AJ5: 188 | AK5: =+AJ5/AJ9 -> 0.0085454545 | AL5: 316 | AM5: =+AL5/AL9 -> 0.011322107 | AN5: 417 | AO5: =+AN5/$AN$9 -> 0.012198333 | AP5: 480 | AQ5: =+AP5/$AP$9 -> 0.01615074 | AR5: 529 | AS5: =+AR5/$AR$9 -> 0.01524276 | AT5: 679 | AU5: =+AT5/$AT$9 -> 0.021651095 | AV5: =+N4 -> 426 | AW5: =+AV5/AV9 -> 0.017715308
A6: Pick Up | B6: 557 | C6: 627 | D6: 938 | E6: 1303 | F6: 1157 | G6: 733 | N6: =SUM(B6:M6) -> 5315 | O6: =+N6/$N$8 -> 0.22102549 | Q6: Minibus | R6: 286 | S6: =+R6/$R$9 -> 0.0097305389 | T6: 365 | U6: =+T6/$T$9 -> 0.012635442 | V6: 398 | W6: =+V6/$V$9 -> 0.014118482 | X6: 408 | Y6: =+X6/X9 -> 0.013293799 | Z6: 285 | AA6: =+Z6/Z9 -> 0.011604707 | AB6: 163 | AC6: =+AB6/AB9 -> 0.007835785 | AD6: 197 | AE6: =+AD6/AD9 -> 0.0070733546 | AF6: 163 | AG6: =+AF6/$AF$9 -> 0.0045416551 | AH6: 177 | AI6: 0.0062242853 | AJ6: 106 | AK6: =+AJ6/AJ9 -> 0.0048181818 | AL6: 124 | AM6: =+AL6/AL9 -> 0.004442852 | AN6: 271 | AO6: =+AN6/$AN$9 -> 0.0079274536 | AP6: 251 | AQ6: =+AP6/$AP$9 -> 0.0084454913 | AR6: 373 | AS6: =+AR6/$AR$9 -> 0.010747731 | AT6: 277 | AU6: =+AT6/$AT$9 -> 0.0088326265 | AV6: =+N5 -> 141 | AW6: =+AV6/AV9 -> 0.0058635173
A7: SUV | B7: 2102 | C7: 2247 | D7: 2612 | E7: 2724 | F7: 2588 | G7: 2912 | N7: =SUM(B7:M7) -> 15185 | O7: =+N7/$N$8 -> 0.6314717 | Q7: Pick Up | R7: 10326 | S7: =+R7/$R$9 -> 0.35132009 | T7: 10303 | U7: =+T7/$T$9 -> 0.35666563 | V7: 8759 | W7: =+V7/$V$9 -> 0.31071302 | X7: 8557 | Y7: =+X7/X9 -> 0.27881138 | Z7: 7465 | AA7: =+Z7/Z9 -> 0.30396189 | AB7: 5823 | AC7: =+AB7/AB9 -> 0.27992501 | AD7: 8478 | AE7: =+AD7/AD9 -> 0.30440559 | AF7: 9645 | AG7: =+AF7/$AF$9 -> 0.26873781 | AH7: 6167 | AI7: 0.21686535 | AJ7: 4440 | AK7: =+AJ7/AJ9 -> 0.20181818 | AL7: 7737 | AM7: =+AL7/AL9 -> 0.27721247 | AN7: 7997 | AO7: =+AN7/$AN$9 -> 0.23393301 | AP7: 8292 | AQ7: =+AP7/$AP$9 -> 0.27900404 | AR7: 9267 | AS7: =+AR7/$AR$9 -> 0.26702204 | AT7: 7317 | AU7: =+AT7/$AR$9 -> 0.21083417 | AV7: =+N6 -> 5315 | AW7: =+AV7/AV9 -> 0.22102549
A8: Total vehículos | B8: =SUM(B3:B7) -> 3205 | C8: =SUM(C3:C7) -> 3319 | D8: =SUM(D3:D7) -> 4038 | E8: =SUM(E3:E7) -> 4624 | F8: =SUM(F3:F7) -> 4341 | G8: =SUM(G3:G7) -> 4520 | H8: =SUM(H3:H7) -> 0 | I8: =SUM(I3:I7) -> 0 | ... N8: =SUM(N3:N7) -> 24047 | O8: =+N8/$N$8 -> 1 | Q8: SUV | R8: 6380 | S8: =+R8/$R$9 -> 0.21706587 | T8: 6561 | U8: =+T8/$T$9 -> 0.22712639 | V8: 5623 | W8: =+V8/$V$9 -> 0.1994679 | X8: 7590 | Y8: =+X8/X9 -> 0.24730377 | Z8: 7114 | AA8: =+Z8/Z9 -> 0.28966977 | AB8: 6548 | AC8: =+AB8/AB9 -> 0.31477743 | AD8: 7902 | AE8: =+AD8/AD9 -> 0.2837241 | AF8: 10458 | AG8: =+AF8/$AF$9 -> 0.29139036 | AH8: 8708 | AI8: 0.30622077 | AJ8: 6439 | AK8: =+AJ8/AJ9 -> 0.29268182 | AL8: 8843 | AM8: =+AL8/AL9 -> 0.31683984 | AN8: 16121 | AO8: =+AN8/$AN$9 -> 0.4715811 | AP8: 14641 | AQ8: =+AP8/$AP$9 -> 0.49263122 | AR8: 18477 | AS8: =+AR8/$AR$9 -> 0.53240167 | AT8: 17954 | AU8: =+AT8/$AR$9 -> 0.5173318 | AV8: =+N7 -> 15185 | AW8: =+AV8/AV9 -> 0.6314717
A9: Crec, % mes | C9: =+C8/B8-1 -> 0.035569423 | D9: =+D8/C8-1 -> 0.21663152 | E9: =+E8/D8-1 -> 0.14512135 | F9: =+F8/E8-1 -> -0.061202422 | G9: =+G8/F8-1 -> 0.041234739 | H9: =+H8/G8-1 -> -1 | I9: =+I8/H8-1 -> #DIV/0! | J9: =+J8/I8-1 -> #DIV/0! | ... M9: =+M8/L8-1 -> #DIV/0! | Q9: Total | R9: =SUM(R4:R8) -> 29392 | S9: =SUM(S4:S8) -> 1 | T9: =SUM(T4:T8) -> 28887 | U9: =SUM(U4:U8) -> 1 | V9: =SUM(V4:V8) -> 28190 | W9: =SUM(W4:W8) -> 1 | X9: =SUM(X4:X8) -> 30691 | Y9: =SUM(Y4:Y8) -> 1 | ... AN9: =SUM(AN4:AN8) -> 34185 | AO9: =+AN9/$AN$9 -> 1 | AP9: =SUM(AP4:AP8) -> 29720 | AQ9: =+AP9/$AP$9 -> 1 | AR9: =SUM(AR4:AR8) -> 34705 | AS9: =+AR9/$AR$9 -> 1 | AT9: =SUM(AT4:AT8) -> 31361 | AV9: =SUM(AV4:AV8) -> 24047 | AW9: =SUM(AW4:AW8) -> 1
A10: Fuente: CADAM | Q10: Fuente: CADAM

Sheet 4
A1: Cuadro 4: Importación de vehículos variación mensual, 2025-2026 | P1: Cuadro 16: Importación de camiones, variación mensual, 2019-2020 | W1: Variación mensual autos y camiones 2020
A2: MESES | B2: 2025 | C2: Var. % 2025 | D2: 2026 | E2: Var. % 2026 | F2: Var. % 2026/2025 | P2: Meses | Q2: 2019 | R2: var. % 2019 | S2: 2020 | T2: var. % 2020 | U2: Var % 2020/2019 | W2: Meses | X2: 2019 | Y2: var. % 2019 | Z2: 2020 | AA2: var. % 2020
A4: Ene | B4: 2649 | C4: - | D4: 3205 | F4: =+D4/B4-1 -> 0.20989052 | P4: Ene | Q4: 274 | R4: - | S4: 253 | T4: - | U4: =+S4/Q4-1 -> -0.076642336 | W4: Ene | X4: =+B4+Q4 -> 2923 | Z4: =+D4+S4 -> 3458
A5: Feb | B5: 2457 | C5: =+B5/B4-1 -> -0.072480181 | D5: 3319 | E5: =+D5/D4-1 -> 0.035569423 | F5: =+D5/B5-1 -> 0.35083435 | P5: Feb | Q5: 242 | R5: =+Q5/Q4-1 -> -0.11678832 | S5: 190 | T5: =+S5/S4-1 -> -0.24901186 | U5: =+S5/Q5-1 -> -0.21487603 | W5: Feb | X5: =+B5+Q5 -> 2699 | Y5: =+X5/X4-1 -> -0.076633596 | Z5: =+D5+S5 -> 3509 | AA5: =+Z5/Z4-1 -> 0.014748409
A6: Mar | B6: 2913 | C6: =+B6/B5-1 -> 0.18559219 | D6: 4038 | E6: =+D6/D5-1 -> 0.21663152 | F6: =+D6/B6-1 -> 0.38619979 | P6: Mar | Q6: 313 | R6: =+Q6/Q5-1 -> 0.29338843 | S6: 93 | T6: =+S6/S5-1 -> -0.51052632 | U6: =+S6/Q6-1 -> -0.7028754 | W6: Mar | X6: =+B6+Q6 -> 3226 | Y6: =+X6/X5-1 -> 0.1952575 | Z6: =+D6+S6 -> 4131 | AA6: =+Z6/Z5-1 -> 0.17725848
A7: Abr | B7: 2537 | C7: =+B7/B6-1 -> -0.12907655 | D7: 4624 | E7: =+D7/D6-1 -> 0.14512135 | F7: =+D7/B7-1 -> 0.82262515 | P7: Abr | Q7: 233 | R7: =+Q7/Q6-1 -> -0.25559105 | T7: =+S7/S6-1 -> -1 | U7: =+S7/Q7-1 -> -1 | W7: Total | X7: =SUM(X4:X6) -> 8848 | Z7: =SUM(Z4:Z6) -> 11098
A8: May | B8: 2940 | C8: =+B8/B7-1 -> 0.15884903 | D8: 4341 | E8: =+D8/D7-1 -> -0.061202422 | F8: =+D8/B8-1 -> 0.47653061 | P8: May | Q8: 153 | R8: =+Q8/Q7-1 -> -0.34334764 | T8: =+S8/S7-1 -> #DIV/0! | U8: =+S8/Q8-1 -> -1 | Z8: =+Z7/X7-1 -> 0.25429476
A9: Jun | B9: 3354 | C9: =+B9/B8-1 -> 0.14081633 | D9: 4520 | E9: =+D9/D8-1 -> 0.041234739 | F9: =+D9/B9-1 -> 0.3476446 | P9: Jun | Q9: 96 | R9: =+Q9/Q8-1 -> -0.37254902 | T9: =+S9/S8-1 -> #DIV/0! | U9: =+S9/Q9-1 -> -1
A10: Jul | B10: 3480 | C10: =+B10/B9-1 -> 0.037567084 | E10: =+D10/D9-1 -> -1 | F10: =+D10/B10-1 -> -1 | P10: Jul | Q10: 188 | R10: =+Q10/Q9-1 -> 0.95833333 | T10: =+S10/S9-1 -> #DIV/0! | U10: =+S10/Q10-1 -> -1
A11: Ago | B11: 3330 | C11: =+B11/B10-1 -> -0.043103448 | E11: =+D11/D10-1 -> #DIV/0! | F11: =+D11/B11-1 -> -1 | P11: Ago | Q11: 173 | R11: =+Q11/Q10-1 -> -0.079787234 | T11: =+S11/S10-1 -> #DIV/0! | U11: =+S11/Q11-1 -> -1
A12: Sep | B12: 3197 | C12: =+B12/B11-1 -> -0.03993994 | E12: =+D12/D11-1 -> #DIV/0! | F12: =+D12/B12-1 -> -1 | P12: Sep | Q12: 146 | R12: =+Q12/Q11-1 -> -0.15606936 | T12: =+S12/S11-1 -> #DIV/0! | U12: =+S12/Q12-1 -> -1
A13: Oct | B13: 4504 | C13: =+B13/B12-1 -> 0.40882077 | E13: =+D13/D12-1 -> #DIV/0! | F13: =+D13/B13-1 -> -1 | P13: Oct | Q13: 108 | R13: =+Q13/Q12-1 -> -0.26027397 | T13: =+S13/S12-1 -> #DIV/0! | U13: =+S13/Q13-1 -> -1
A14: Nov | B14: 3540 | C14: =+B14/B13-1 -> -0.21403197 | E14: =+D14/D13-1 -> #DIV/0! | F14: =+D14/B14-1 -> -1 | P14: Nov | Q14: 232 | R14: =+Q14/Q13-1 -> 1.1481481 | T14: =+S14/S13-1 -> #DIV/0! | U14: =+S14/Q14-1 -> -1
A15: Dic | B15: 3710 | C15: =+B15/B14-1 -> 0.048022599 | E15: =+D15/D14-1 -> #DIV/0! | F15: =+D15/B15-1 -> -1 | P15: Dic | Q15: 140 | R15: =+Q15/Q14-1 -> -0.39655172 | T15: =+S15/S14-1 -> #DIV/0! | U15: =+S15/Q15-1 -> -1
A16: Total | B16: =SUM(B4:B9) -> 16850 | C16: - | D16: =SUM(D4:D15) -> 24047 | E16: - | F16: =+D16/B16-1 -> 0.42712166 | P16: Total | Q16: =SUM(Q4:Q6) -> 829 | S16: =SUM(S4:S15) -> 536 | U16: =+S16/Q16-1 -> -0.35343788
A17: Fuente: CADAM
A34: Cuadro 4B: Importación de vehículos variación mensual, 2023-2024 | G34: Proyección | P34: Cuadro 4C: Importación de vehículos y camiones variación mensual, 2018-2019 | V34: Proyección
A35: MESES | B35: 2023 | C35: var. % 2023 | D35: 2024 | E35: var. % 2024 | F35: Var. % 2024/2023 | P35: MESES | Q35: 2018 | R35: var. % 2018 | S35: 2019 | T35: var. % 2019 | U35: Var. % 2019/2018
A37: Ene | B37: 1939 | C37: - | D37: 2037 | E37: - | F37: =+D37/B37-1 -> 0.050541516 | P37: Ene | Q37: =+B37+'16'!B44 -> 2043 | R37: - | S37: =+D37+'16'!D44 -> 2185 | T37: - | U37: =+S37/Q37-1 -> 0.069505629
A38: Feb | B38: 2451 | C38: =+B38/B37-1 -> 0.26405364 | E38: =+D38/D37-1 -> -1 | F38: =+D38/B38-1 -> -1 | P38: Feb | Q38: =+B38+'16'!B45 -> 2597 | R38: =+Q38/Q37-1 -> 0.27116985 | S38: =+D38+'16'!D45 -> 0 | T38: =+S38/S37-1 -> -1 | U38: =+S38/Q38-1 -> -1
A39: Mar | B39: 2752 | C39: =+B39/B38-1 -> 0.12280702 | E39: =+D39/D38-1 -> #DIV/0! | F39: =+D39/B39-1 -> -1 | P39: Mar | Q39: =+B39+'16'!B46 -> 2879 | R39: =+Q39/Q38-1 -> 0.10858683 | S39: =+D39+'16'!D46 -> 0 | T39: =+S39/S38-1 -> #DIV/0! | U39: =+S39/Q39-1 -> -1
A40: Abr | B40: 2336 | C40: =+B40/B39-1 -> -0.15116279 | E40: =+D40/D39-1 -> #DIV/0! | F40: =+D40/B40-1 -> -1 | P40: Abr | Q40: =+B40+'16'!B47 -> 2566 | R40: =+Q40/Q39-1 -> -0.1087183 | S40: =+D40+'16'!D47 -> 0 | T40: =+S40/S39-1 -> #DIV/0! | U40: =+S40/Q40-1 -> -1
A41: May | B41: 2590 | C41: =+B41/B40-1 -> 0.10873288 | E41: =+D41/D40-1 -> #DIV/0! | F41: =+D41/B41-1 -> -1 | P41: May | Q41: =+B41+'16'!B48 -> 2662 | R41: =+Q41/Q40-1 -> 0.037412315 | S41: =+D41+'16'!D48 -> 0 | T41: =+S41/S40-1 -> #DIV/0! | U41: =+S41/Q41-1 -> -1
A42: Jun | B42: 2496 | C42: =+B42/B41-1 -> -0.036293436 | E42: =+D42/D41-1 -> #DIV/0! | F42: =+D42/B42-1 -> -1 | P42: Jun | Q42: =+B42+'16'!B49 -> 2624 | R42: =+Q42/Q41-1 -> -0.014274981 | S42: =+D42+'16'!D49 -> 0 | T42: =+S42/S41-1 -> #DIV/0! | U42: =+S42/Q42-1 -> -1
A43: Jul | B43: 2619 | C43: =+B43/B42-1 -> 0.049278846 | E43: =+D43/D42-1 -> #DIV/0! | F43: =+D43/B43-1 -> -1 | P43: Jul | Q43: =+B43+'16'!B50 -> 2842 | R43: =+Q43/Q42-1 -> 0.083079268 | S43: =+D43+'16'!D50 -> 0 | T43: =+S43/S42-1 -> #DIV/0! | U43: =+S43/Q43-1 -> -1
A44: Ago | B44: 2707 | C44: =+B44/B43-1 -> 0.033600611 | E44: =+D44/D43-1 -> #DIV/0! | F44: =+D44/B44-1 -> -1 | P44: Ago | Q44: =+B44+'16'!B51 -> 2836 | R44: =+Q44/Q43-1 -> -0.0021111893 | S44: =+D44+'16'!D51 -> 0 | T44: =+S44/S43-1 -> #DIV/0! | U44: =+S44/Q44-1 -> -1
A45: Sep | B45: 2373 | C45: =+B45/B44-1 -> -0.12338382 | E45: =+D45/D44-1 -> #DIV/0! | F45: =+D45/B45-1 -> -1 | P45: Sep | Q45: =+B45+'16'!B52 -> 2522 | R45: =+Q45/Q44-1 -> -0.11071932 | S45: =+D45+'16'!D52 -> 0 | T45: =+S45/S44-1 -> #DIV/0! | U45: =+S45/Q45-1 -> -1
A46: Oct | B46: 2553 | C46: =+B46/B45-1 -> 0.07585335 | E46: =+D46/D45-1 -> #DIV/0! | F46: =+D46/B46-1 -> -1 | P46: Oct | Q46: =+B46+'16'!B53 -> 2685 | R46: =+Q46/Q45-1 -> 0.064631245 | S46: =+D46+'16'!D53 -> 0 | T46: =+S46/S45-1 -> #DIV/0! | U46: =+S46/Q46-1 -> -1
A47: Nov | B47: 2346 | C47: =+B47/B46-1 -> -0.081081081 | E47: =+D47/D46-1 -> #DIV/0! | F47: =+D47/B47-1 -> -1 | P47: Nov | Q47: =+B47+'16'!B54 -> 2613 | R47: =+Q47/Q46-1 -> -0.026815642 | S47: =+D47+'16'!D54 -> 0 | T47: =+S47/S46-1 -> #DIV/0! | U47: =+S47/Q47-1 -> -1
A48: Dic | B48: 2558 | C48: =+B48/B47-1 -> 0.090366581 | E48: =+D48/D47-1 -> #DIV/0! | F48: =+D48/B48-1 -> -1 | P48: Dic | Q48: =+B48+'16'!B55 -> 2672 | R48: =+Q48/Q47-1 -> 0.022579411 | S48: =+D48+'16'!D55 -> 0 | T48: =+S48/S47-1 -> #DIV/0! | U48: =+S48/Q48-1 -> -1
A49: Total | B49: =SUM(B37:B48) -> 29720 | C49: - | D49: =SUM(D37:D48) -> 2037 | E49: =+D49/B49-1 -> -0.9314603 | F49: =+D49/B49-1 -> -0.9314603 | P49: Total | Q49: =SUM(Q37:Q48) -> 31541 | R49: - | S49: =SUM(S37:S48) -> 2185 | T49: =+S49/Q49-1 -> -0.93072509 | U49: =+S49/Q49-1 -> -0.93072509
P53: 2020 | S53: 32000 | T53: =+S53/S49-1 -> 13.645309

Sheet 5
A1: Cuadro 5: Importación de vehículos por marca y mes, 2026
A2: MARCA | B2: Ene | C2: Feb | D2: Mar | E2: Abr | F2: May | G2: Jun | H2: Jul | I2: Ago | J2: Sep | K2: Oct | L2: Nov | M2: Dic | N2: Total | O2: % | Q2: MARCA | R2: Unidades | S2: % | T2: % Acum | V2: Grafico 5: Ranking de principales marcas importadas, 2026
A3: AION | B3: 4 | C3: 6 | D3: 0 | E3: 9 | F3: 0 | G3: 0 | N3: =SUM(B3:M3) -> 19 | O3: =+N3/$N$79 -> 0.00079011935 | Q3: TOYOTA | R3: 3237 | S3: =+R3/$R$79 -> 0.13461139 | T3: =+S3 -> 0.13461139
A4: ARCFOX | B4: 0 | C4: 0 | D4: 0 | E4: 0 | F4: 2 | G4: 0 | N4: =SUM(B4:M4) -> 2 | O4: =+N4/$N$79 -> 8.3170458e-05 | Q4: KIA | R4: 2394 | S4: =+R4/$R$79 -> 0.099555038 | T4: =+S4+T3 -> 0.23416642
A5: AUDI | B5: 21 | C5: 20 | D5: 19 | E5: 14 | F5: 13 | G5: 11 | N5: =SUM(B5:M5) -> 98 | O5: =+N5/$N$79 -> 0.0040753524 | Q5: HYUNDAI | R5: 2248 | S5: =+R5/$R$79 -> 0.093483595 | T5: =+S5+T4 -> 0.32765002
A6: AVATR | B6: 0 | C6: 0 | D6: 10 | E6: 7 | F6: 0 | G6: 4 | N6: =SUM(B6:M6) -> 21 | O6: =+N6/$N$79 -> 0.00087328981 | Q6: FIAT | R6: 2213 | S6: =+R6/$R$79 -> 0.092028112 | T6: =+S6+T5 -> 0.41967813
A7: BAIC | B7: 6 | C7: 24 | D7: 16 | E7: 0 | F7: 14 | G7: 14 | N7: =SUM(B7:M7) -> 74 | O7: =+N7/$N$79 -> 0.0030773069 | Q7: CHEVROLET | R7: 2144 | S7: =+R7/$R$79 -> 0.089158731 | T7: =+S7+T6 -> 0.50883686
A8: BAOJUN | B8: 0 | C8: 0 | D8: 0 | E8: 0 | F8: 3 | G8: 0 | N8: =SUM(B8:M8) -> 3 | O8: =+N8/$N$79 -> 0.00012475569 | Q8: VOLKSWAGEN | R8: 1461 | S8: =+R8/$R$79 -> 0.060756019 | T8: =+S8+T7 -> 0.56959288
A9: BMW | B9: 20 | C9: 37 | D9: 39 | E9: 50 | F9: 14 | G9: 33 | N9: =SUM(B9:M9) -> 193 | O9: =+N9/$N$79 -> 0.0080259492 | Q9: SUZUKI | R9: 1164 | S9: =+R9/$R$79 -> 0.048405206 | T9: =+S9+T8 -> 0.61799809
A10: BYD | B10: 11 | C10: 18 | D10: 124 | E10: 22 | F10: 100 | G10: 6 | N10: =SUM(B10:M10) -> 281 | O10: =+N10/$N$79 -> 0.011685449 | Q10: NISSAN | R10: 965 | S10: =+R10/$R$79 -> 0.040129746 | T10: =+S10+T9 -> 0.65812783
A11: CADILLAC | B11: 0 | C11: 0 | D11: 0 | E11: 1 | F11: 0 | G11: 0 | N11: =SUM(B11:M11) -> 1 | O11: =+N11/$N$79 -> 4.1585229e-05 | Q11: CHERY | R11: 882 | S11: =+R11/$R$79 -> 0.036678172 | T11: =+S11+T10 -> 0.694806
A12: CHANGAN | B12: 15 | C12: 71 | D12: 57 | E12: 39 | F12: 36 | G12: 9 | N12: =SUM(B12:M12) -> 227 | O12: =+N12/$N$79 -> 0.009439847 | Q12: GEELY | R12: 832 | S12: =+R12/$R$79 -> 0.03459891 | T12: =+S12+T11 -> 0.72940492
A13: CHERY | B13: 60 | C13: 238 | D13: 101 | E13: 319 | F13: 140 | G13: 24 | N13: =SUM(B13:M13) -> 882 | O13: =+N13/$N$79 -> 0.036678172 | Q13: JETOUR | R13: 583 | S13: =+R13/$R$79 -> 0.024244188 | T13: =+S13+T12 -> 0.7536491
A14: CHEVROLET | B14: 219 | C14: 221 | D14: 551 | E14: 236 | F14: 449 | G14: 468 | N14: =SUM(B14:M14) -> 2144 | O14: =+N14/$N$79 -> 0.089158731 | Q14: MG | R14: 558 | S14: =+R14/$R$79 -> 0.023204558 | T14: =+S14+T13 -> 0.77685366
A15: CITROEN | B15: 14 | C15: 9 | D15: 10 | E15: 16 | F15: 42 | G15: 0 | N15: =SUM(B15:M15) -> 91 | O15: =+N15/$N$79 -> 0.0037842558 | Q15: MAZDA | R15: 440 | S15: =+R15/$R$79 -> 0.018297501 | T15: =+S15+T14 -> 0.79515116
... A78: YUFENG | B78: 0 | C78: 0 | D78: 0 | E78: 0 | F78: 0 | G78: 2 | N78: =SUM(B78:M78) -> 2 | O78: =+N78/$N$79 -> 8.3170458e-05 | Q78: VOYAH DREAMER | R78: 1 | S78: =+R78/$R$79 -> 4.1585229e-05 | T78: =+S78+T77 -> 1
A79: Total | B79: =SUM(B3:B78) -> 3205 | C79: =SUM(C3:C78) -> 3319 | D79: =SUM(D3:D78) -> 4038 | E79: =SUM(E3:E78) -> 4624 | F79: =SUM(F3:F78) -> 4341 | G79: =SUM(G3:G78) -> 4520 | H79: =SUM(H3:H78) -> 0 | I79: =SUM(I3:I78) -> 0 | ... O79: =SUM(O3:O78) -> 1 | Q79: Total | R79: =SUM(R3:R78) -> 24047 | S79: =SUM(S3:S78) -> 1
A80: Fuente: CADAM | B80: 3205 | C80: 3319 | D80: 4038 | E80: 4624 | F80: 4341 | G80: 4520
A84: Cuadro 5A: Importación de vehículos por marca y mes | O84: Grafico 5A: Variación de importacipon de vehículos, por marca, 2026
A85: MARCAS | B85: 45809 | C85: 46174 | D85: Var % 2026/2025 | E85: Part. en total | F85: Var. Unid.
A86: TOYOTA | B86: 2151 | C86: 3237 | D86: =+C86/B86-1 -> 0.50488145 | E86: =+C86/$C$171 -> 0.13461139 | F86: =+C86-B86 -> 1086
A87: KIA | B87: 2295 | C87: 2394 | D87: =+C87/B87-1 -> 0.043137255 | E87: =+C87/$C$171 -> 0.099555038 | F87: =+C87-B87 -> 99
A88: HYUNDAI | B88: 1969 | C88: 2248 | D88: =+C88/B88-1 -> 0.14169629 | E88: =+C88/$C$171 -> 0.093483595 | F88: =+C88-B88 -> 279
A89: FIAT | B89: 1236 | C89: 2213 | D89: =+C89/B89-1 -> 0.79045307 | E89: =+C89/$C$171 -> 0.092028112 | F89: =+C89-B89 -> 977
A90: CHEVROLET | B90: 1242 | C90: 2144 | D90: =+C90/B90-1 -> 0.72624799 | E90: =+C90/$C$171 -> 0.089158731 | F90: =+C90-B90 -> 902
A91: VOLKSWAGEN | B91: 1166 | C91: 1461 | D91: =+C91/B91-1 -> 0.25300172 | E91: =+C91/$C$171 -> 0.060756019 | F91: =+C91-B91 -> 295
A92: SUZUKI | B92: 857 | C92: 1164 | D92: =+C92/B92-1 -> 0.35822637 | E92: =+C92/$C$171 -> 0.048405206 | F92: =+C92-B92 -> 307
A93: NISSAN | B93: 890 | C93: 965 | D93: =+C93/B93-1 -> 0.084269663 | E93: =+C93/$C$171 -> 0.040129746 | F93: =+C93-B93 -> 75
A94: CHERY | B94: 274 | C94: 882 | D94: =+C94/B94-1 -> 2.2189781 | E94: =+C94/$C$171 -> 0.036678172 | F94: =+C94-B94 -> 608
A95: GEELY | B95: 553 | C95: 832 | D95: =+C95/B95-1 -> 0.5045208 | E95: =+C95/$C$171 -> 0.03459891 | F95: =+C95-B95 -> 279
A96: JETOUR | B96: 281 | C96: 583 | D96: =+C96/B96-1 -> 1.0747331 | E96: =+C96/$C$171 -> 0.024244188 | F96: =+C96-B96 -> 302
A97: MG | B97: 131 | C97: 558 | D97: =+C97/B97-1 -> 3.259542 | E97: =+C97/$C$171 -> 0.023204558 | F97: =+C97-B97 -> 427
... A170: ZEEKR | B170: 9 | C170: 0 | D170: =+C170/B170-1 -> -1 | E170: =+C170/$C$171 -> 0 | F170: =+C170-B170 -> -9
A171: Total | B171: =SUM(B86:B170) -> 16850 | C171: =SUM(C86:C170) -> 24047 | D171: =+C171/B171-1 -> 0.42712166 | E171: =SUM(E86:E170) -> 1

Sheet 6
A1: Cuadro 6: Importación de vehículos por país de procedencia y mes, 2026
A2: Procedencia | B2: Ene | C2: Feb | D2: Mar | E2: Abr | F2: May | G2: Jun | H2: Jul | I2: Ago | J2: Set | K2: Oct | L2: Nov | M2: Dic | N2: Total | O2: % | Q2: Procedencia | R2: % | S2: % Acum | T2: Acum %
A3: ALEMANIA | B3: 41 | C3: 43 | D3: 59 | E3: 35 | F3: 23 | G3: 43 | N3: =SUM(B3:M3) -> 244 | O3: =+N3/$N$25 -> 0.010146796 | Q3: BRASIL | R3: 0.36179149 | S3: =+R3 -> 0.36179149 | T3: =+R3 -> 0.36179149
A4: ARGENTINA | B4: 110 | C4: 228 | D4: 273 | E4: 430 | F4: 465 | G4: 208 | N4: =SUM(B4:M4) -> 1714 | O4: =+N4/$N$25 -> 0.071277082 | Q4: CHINA | R4: 0.26531376 | S4: =+R4+S3 -> 0.62710525 | T4: =+R4+T3 -> 0.62710525
A5: AUSTRIA | B5: 1 | C5: 1 | D5: 0 | E5: 1 | F5: 1 | G5: 3 | N5: =SUM(B5:M5) -> 7 | O5: =+N5/$N$25 -> 0.0002910966 | Q5: ARGENTINA | R5: 0.071277082 | T5: =+R5+T4 -> 0.69838233
A6: BELGICA | B6: 0 | C6: 0 | D6: 2 | E6: 2 | F6: 0 | G6: 1 | N6: =SUM(B6:M6) -> 5 | O6: =+N6/$N$25 -> 0.00020792614 | Q6: INDIA | R6: 0.071069156 | T6: =+R6+T5 -> 0.76945149
A7: BRASIL | B7: 958 | C7: 1038 | D7: 1583 | E7: 1736 | F7: 1570 | G7: 1815 | N7: =SUM(B7:M7) -> 8700 | O7: =+N7/$N$25 -> 0.36179149 | Q7: COREA DEL SUR | R7: 0.059134196 | T7: =+R7+T6 -> 0.82858569
A8: CANADA | B8: 0 | C8: 2 | D8: 1 | E8: 0 | F8: 2 | G8: 1 | N8: =SUM(B8:M8) -> 6 | O8: =+N8/$N$25 -> 0.00024951137 | Q8: JAPON | R8: 0.042250593 | T8: =+R8+T7 -> 0.87083628
A9: CHINA | B9: 906 | C9: 965 | D9: 1211 | E9: 1356 | F9: 914 | G9: 1028 | N9: =SUM(B9:M9) -> 6380 | O9: =+N9/$N$25 -> 0.26531376 | Q9: INDONESIA | R9: 0.037676217 | S9: =+R9+S4 -> 0.66478147 | T9: =+R9+T8 -> 0.9085125
A10: COREA DEL SUR | B10: 240 | C10: 241 | D10: 271 | E10: 176 | F10: 265 | G10: 229 | N10: =SUM(B10:M10) -> 1422 | O10: =+N10/$N$25 -> 0.059134196 | Q10: TAILANDIA | R10: 0.029192831 | T10: =+R10+T9 -> 0.93770533
A11: EMIRATOS ARABES UNIDOS | B11: 2 | C11: 2 | D11: 0 | E11: 0 | F11: 0 | G11: 0 | N11: =SUM(B11:M11) -> 4 | O11: =+N11/$N$25 -> 0.00016634092 | Q11: MEXICO | R11: 0.02545016 | S11: =+R11+S9 -> 0.69023163 | T11: =+R11+T10 -> 0.96315549
A12: ESLOVAQUIA | B12: 6 | C12: 7 | D12: 9 | E12: 16 | F12: 3 | G12: 6 | N12: =SUM(B12:M12) -> 47 | O12: =+N12/$N$25 -> 0.0019545058 | Q12: EE.UU. | R12: 0.014305319 | T12: =+R12+T11 -> 0.97746081
A13: EE.UU. | B13: 65 | C13: 70 | D13: 60 | E13: 56 | F13: 40 | G13: 53 | N13: =SUM(B13:M13) -> 344 | O13: =+N13/$N$25 -> 0.014305319 | Q13: ALEMANIA | R13: 0.010146796 | S13: =+R13+S11 -> 0.70037843 | T13: =+R13+T12 -> 0.9876076
A14: FRANCIA | B14: 4 | C14: 3 | D14: 16 | E14: 3 | F14: 1 | G14: 0 | N14: =SUM(B14:M14) -> 27 | O14: =+N14/$N$25 -> 0.0011228012 | Q14: REINO UNIDO | R14: 0.0046159604 | S14: =+R14+S13 -> 0.70499439 | T14: =+R14+T13 -> 0.99222356
A15: HUNGRIA | B15: 6 | C15: 1 | D15: 1 | E15: 1 | F15: 0 | G15: 2 | N15: =SUM(B15:M15) -> 11 | O15: =+N15/$N$25 -> 0.00045743752 | Q15: SUECIA | R15: 0.0027446251 | S15: =+R15+S14 -> 0.70773901 | T15: =+R15+T14 -> 0.99496819
A16: INDIA | B16: 348 | C16: 163 | D16: 45 | E16: 281 | F16: 360 | G16: 512 | N16: =SUM(B16:M16) -> 1709 | O16: =+N16/$N$25 -> 0.071069156 | Q16: ESLOVAQUIA | R16: 0.0019545058 | S16: =+R16+S15 -> 0.70969352 | T16: =+R16+T15 -> 0.99692269
A17: INDONESIA | B17: 146 | C17: 141 | D17: 168 | E17: 58 | F17: 209 | G17: 184 | N17: =SUM(B17:M17) -> 906 | O17: =+N17/$N$25 -> 0.037676217 | Q17: FRANCIA | R17: 0.0011228012 | T17: =+R17+T16 -> 0.99804549
A18: ITALIA | B18: 0 | C18: 0 | D18: 0 | E18: 0 | F18: 1 | G18: 1 | N18: =SUM(B18:M18) -> 2 | O18: =+N18/$N$25 -> 8.3170458e-05 | Q18: SUDAFRICA | R18: 0.00049902275 | S18: =+R18+S16 -> 0.71019254 | T18: =+R18+T17 -> 0.99854452
A19: JAPON | B19: 175 | C19: 122 | D19: 99 | E19: 170 | F19: 289 | G19: 161 | N19: =SUM(B19:M19) -> 1016 | O19: =+N19/$N$25 -> 0.042250593 | Q19: HUNGRIA | R19: 0.00045743752 | S19: =+R19+S18 -> 0.71064998 | T19: =+R19+T18 -> 0.99900195
A20: MEXICO | B20: 32 | C20: 194 | D20: 116 | E20: 108 | F20: 80 | G20: 82 | N20: =SUM(B20:M20) -> 612 | O20: =+N20/$N$25 -> 0.02545016 | Q20: AUSTRIA | R20: 0.0002910966 | T20: =+R20+T19 -> 0.99929305
A21: REINO UNIDO | B21: 38 | C21: 1 | D21: 42 | E21: 5 | F21: 9 | G21: 16 | N21: =SUM(B21:M21) -> 111 | O21: =+N21/$N$25 -> 0.0046159604 | Q21: CANADA | R21: 0.00024951137 | S21: =+R21+S19 -> 0.71089949 | T21: =+R21+T20 -> 0.99954256
A22: SUDAFRICA | B22: 1 | C22: 1 | D22: 2 | E22: 7 | F22: 0 | G22: 1 | N22: =SUM(B22:M22) -> 12 | O22: =+N22/$N$25 -> 0.00049902275 | Q22: BELGICA | R22: 0.00020792614 | T22: =+R22+T21 -> 0.99975049
A23: SUECIA | B23: 12 | C23: 26 | D23: 11 | E23: 10 | F23: 0 | G23: 7 | N23: =SUM(B23:M23) -> 66 | O23: =+N23/$N$25 -> 0.0027446251 | Q23: EMIRATOS ARABES UNIDOS | R23: 0.00016634092 | S23: =+R23+S21 -> 0.71106583 | T23: =+R23+T22 -> 0.99991683
A24: TAILANDIA | B24: 114 | C24: 70 | D24: 69 | E24: 173 | F24: 109 | G24: 167 | N24: =SUM(B24:M24) -> 702 | O24: =+N24/$N$25 -> 0.029192831 | Q24: ITALIA | R24: 8.3170458e-05 | T24: =+R24+T23 -> 1
A25: Total | B25: =SUM(B3:B24) -> 3205 | C25: =SUM(C3:C24) -> 3319 | D25: =SUM(D3:D24) -> 4038 | E25: =SUM(E3:E24) -> 4624 | F25: =SUM(F3:F24) -> 4341 | G25: =SUM(G3:G24) -> 4520 | H25: =SUM(H3:H24) -> 0 | I25: =SUM(I3:I24) -> 0 | ... O25: =SUM(O3:O24) -> 1 | Q25: Total | R25: =SUM(R3:R24) -> 1
A26: Fuente: CADAM

Sheet 7
A1: Cuadro 7: Importación de vehículos por empresa y marca, 2024 | R1: *No se disponen datos del importador
A2: Empresa | B2: Marcas | C2: Ene | D2: Feb | E2: Mar | F2: Abr | G2: May | H2: Jun | I2: Jul | J2: Ago | K2: Sep | L2: Oct | M2: Nov | N2: Dic | O2: Total | P2: 0 Km, % del total | S2: Ranking
S3: Empresa | T3: Marca | V3: %
A4: Prestigio Automotores S.A. | B4: AUDI | O4: =SUM(C4:N4) -> 0 | P4: =+O4/$O$105 -> #DIV/0!
A5: Diesa S.A. | B5: AUDI | O5: =SUM(C5:N5) -> 0 | P5: =+O5/$O$105 -> #DIV/0!
A6: Imp. Casual | B6: AUDI | O6: =SUM(C6:N6) -> 0 | P6: =+O6/$O$105 -> #DIV/0!
A7: AMERICAN AUTOMOTORES S A | B7: AIGLE | O7: =SUM(C7:N7) -> 0 | P7: =+O7/$O$105 -> #DIV/0!
A8: Imp. Casual | B8: BAOJUN | O8: =SUM(C8:N8) -> 0 | P8: =+O8/$O$105 -> #DIV/0!
A9: CATHAY S.A. | B9: BAIC | O9: =SUM(C9:N9) -> 0 | P9: =+O9/$O$105 -> #DIV/0!
A10: Imp. Casual | B10: BEIJING | O10: =SUM(C10:N10) -> 0 | P10: =+O10/$O$105 -> #DIV/0!
A11: MERCOTEC S.A.E | B11: BESTUNE | O11: =SUM(C11:N11) -> 0 | P11: =+O11/$O$105 -> #DIV/0!
A12: Perfecta Automotores S.A. | B12: BMW | O12: =SUM(C12:N12) -> 0 | P12: =+O12/$O$105 -> #DIV/0!
A13: Chacomer Automotores S.A. | B13: BRILLIANCE | O13: =SUM(C13:N13) -> 0 | P13: =+O13/$O$105 -> #DIV/0!
A14: Diesa S.A. | B14: BYD | O14: =SUM(C14:N14) -> 0 | P14: =+O14/$O$105 -> #DIV/0!
A15: Imp. casual | B15: BYD | O15: =SUM(C15:N15) -> 0 | P15: =+O15/$O$105 -> #DIV/0!
... A41: Vicar S.A. | B41: HONDA | O41: =SUM(C41:N41) -> 0 | P41: =+O41/$O$105 -> #DIV/0!
A42: Automotor S.A. | B42: HYUNDAI | O42: =SUM(C42:N42) -> 0 | P42: =+O42/$O$105 -> #DIV/0! | Q42: =425-13 -> 412
A43: Automotor S.A. | B43: ISUZU | O43: =SUM(C43:N43) -> 0 | P43: =+O43/$O$105 -> #DIV/0!
A44: Rodomaq | B44: IVECO | O44: =SUM(C44:N44) -> 0 | P44: =+O44/$O$105 -> #DIV/0!
A45: SANTA ROSA PARAGUAY S.A. | B45: JAC | O45: =SUM(C45:N45) -> 0 | P45: =+O45/$O$105 -> #DIV/0!
A46: ACE SAC | B46: Jaguar | O46: =SUM(C46:N46) -> 0 | P46: =+O46/$O$105 -> #DIV/0!
A47: Garden Automotores S.A. | B47: JEEP | O47: =SUM(C47:N47) -> 0 | P47: =+O47/$O$105 -> #DIV/0!
A48: SANTA ROSA PARAGUAY S.A. | B48: JETOUR | O48: =SUM(C48:N48) -> 0 | P48: =+O48/$O$105 -> #DIV/0!
A49: TONINA S.A. | B49: JIANGSU | O49: =SUM(C49:N49) -> 0 | P49: =+O49/$O$105 -> #DIV/0!
A50: Chacomer Automotores S.A. | B50: Jim | O50: =SUM(C50:N50) -> 0 | P50: =+O50/$O$105 -> #DIV/0!
A51: Chacomer Automotores S.A. | B51: JMC | O51: =SUM(C51:N51) -> 0 | P51: =+O51/$O$105 -> #DIV/0!
A52: GOLDEN ARROW S.A. | B52: KAIYI | O52: =SUM(C52:N52) -> 0 | P52: =+O52/$O$105 -> #DIV/0!
A53: Imp. Casual | B53: KAIYUN | O53: =SUM(C53:N53) -> 0 | P53: =+O53/$O$105 -> #DIV/0!
A54: SANTA ROSA PARAGUAY S.A. | B54: KARRY | O54: =SUM(C54:N54) -> 0 | P54: =+O54/$O$105 -> #DIV/0!
... A88: Automotor S.A. | B88: RIDDARA | O88: =SUM(C88:N88) -> 0 | P88: =+O88/$O$105 -> #DIV/0!
A89: DOSZETAS SA | B89: SKODA | O89: =SUM(C89:N89) -> 0 | P89: =+O89/$O$105 -> #DIV/0! | S89: Total | U89: =SUM(U4:U88) -> 0 | V89: =SUM(V4:V88) -> 0
A90: Automotor S.A. | B90: SMART | O90: =SUM(C90:N90) -> 0 | P90: =+O90/$O$105 -> #DIV/0!
A91: CENSU S.A. | B91: SSANGYONG | O91: =SUM(C91:N91) -> 0 | P91: =+O91/$O$105 -> #DIV/0!
A92: Tokio Motors | B92: SUBARU | O92: =SUM(C92:N92) -> 0 | P92: =+O92/$O$105 -> #DIV/0!
A93: AMERICAN AUTOMOTORES S A | B93: SUNYU | O93: =SUM(C93:N93) -> 0 | P93: =+O93/$O$105 -> #DIV/0!
A94: Chacomer Automotores S.A. | B94: SUZUKI | O94: =SUM(C94:N94) -> 0 | P94: =+O94/$O$105 -> #DIV/0!
A95: AUTO LOGIC S.A. | B95: Tata | O95: =SUM(C95:N95) -> 0 | P95: =+O95/$O$105 -> #DIV/0!
A96: IVONNE MARGOTT BOSCH | B96: Tesla | O96: =SUM(C96:N96) -> 0 | P96: =+O96/$O$105 -> #DIV/0!
A97: Imp. Casual | B97: Tesla | O97: =SUM(C97:N97) -> 0 | P97: =+O97/$O$105 -> #DIV/0!
A98: Toyotoshi S.A. | B98: TOYOTA | O98: =SUM(C98:N98) -> 0 | P98: =+O98/$O$105 -> #DIV/0!
...

Sheet 8
R1: Valor CIF US$ | T1: Valor CIF US$ | V1: Valor CIF US$ | X1: Valor CIF US$ | Z1: Valor CIF US$ | AB1: Valor CIF US$ | AD1: Valor CIF US$ | AF1: Valor CIF US$ | AH1: Valor CIF US$ | AJ1: Valor CIF US$ | AL1: Valor CIF US$ | AN1: Valor CIF US$ | AR1: Reemplazar acumulado por mes
A2: Cuadro 8: Importación de vehículos por modelo, por mes y valor CIF de importación, 2026 | R2: 46023 | T2: 46054 | V2: 46082 | X2: 46113 | Z2: 46143 | AB2: 46174 | AD2: 46204 | AF2: 46235 | AH2: 46266 | AJ2: 45931 | AL2: 45962 | AN2: 45992 | AQ2: Cuadro 8A: Ranking de Importación de automotores por modelo, 2026
A3: Marca | B3: Modelo | C3: Tipo | D3: Ene | E3: Feb | F3: Mar | G3: Abr | H3: May | I3: Jun | J3: Jul | K3: Ago | L3: Sep | M3: Oct | N3: Nov | O3: Dic | P3: Total | Q3: % | R3: Max | S3: Min | T3: Max | U3: Min | V3: Max | W3: Min | X3: Max | Y3: Min | Z3: Max | AA3: Min | AB3: Max | AC3: Min | AD3: Max | AE3: Min | AF3: Max | AG3: Min | AH3: Max | AI3: Min | AJ3: Max | AK3: Min | AL3: Max | AM3: Min | AN3: Max | AO3: Min | AQ3: Ranking | AR3: Marca | AS3: Modelo | AT3: Tipo | AU3: Junio | AV3: %
A4: AIMA | B4: A08 | C4: Auto mediano B | D4: 0 | E4: 0 | F4: 0 | G4: 0 | H4: 0 | I4: 0 | J4: 0 | K4: 0 | L4: 0 | M4: 0 | N4: 0 | O4: 0 | P4: =SUM(D4:O4) -> 0 | Q4: =+P4/$P$766 -> 0 | R4: - | S4: - | AQ4: Toyota Hilux | AR4: TOYOTA | AS4: Hilux | AT4: Pick up mediano | AU4: 1138 | AV4: =+AU4/$AU$391 -> 0.047323991
A5: AION | B5: AHC7000BEVL0L | C5: Auto mediano C | D5: 4 | E5: 0 | F5: 0 | G5: 0 | H5: 0 | I5: 0 | J5: 0 | K5: 0 | L5: 0 | M5: 0 | N5: 0 | O5: 0 | P5: =SUM(D5:O5) -> 4 | Q5: =+P5/$P$766 -> 0.00016634092 | R5: 10720 | S5: 10720 | AQ5: Fiat Strada | AR5: FIAT | AS5: Strada | AT5: Pick up pequeño | AU5: 1034 | AV5: =+AU5/$AU$391 -> 0.042999127
A6: AION | B6: HIPER HT | C6: SUV mediano C | D6: 0 | E6: 0 | F6: 0 | G6: 0 | H6: 0 | I6: 0 | J6: 0 | K6: 0 | L6: 0 | M6: 0 | N6: 0 | O6: 0 | P6: =SUM(D6:O6) -> 0 | Q6: =+P6/$P$766 -> 0 | R6: - | S6: - | AQ6: Chevrolet S10 | AR6: CHEVROLET | AS6: S10 | AT6: Pick up mediano | AU6: 794 | AV6: =+AU6/$AU$391 -> 0.033018672
A7: AION | B7: M8 | C7: Minibus | D7: 0 | E7: 0 | F7: 0 | G7: 0 | H7: 0 | I7: 0 | J7: 0 | K7: 0 | L7: 0 | M7: 0 | N7: 0 | O7: 0 | P7: =SUM(D7:O7) -> 0 | Q7: =+P7/$P$766 -> 0 | R7: - | S7: - | AQ7: Hyundai Creta | AR7: HYUNDAI | AS7: Creta | AT7: SUV mediano B | AU7: 688 | AV7: =+AU7/$AU$391 -> 0.028610638
A8: AION | B8: RT | C8: Auto mediano C | D8: 0 | E8: 0 | F8: 0 | G8: 0 | H8: 0 | I8: 0 | J8: 0 | K8: 0 | L8: 0 | M8: 0 | N8: 0 | O8: 0 | P8: =SUM(D8:O8) -> 0 | Q8: =+P8/$P$766 -> 0 | R8: - | S8: - | AQ8: Kia Soluto | AR8: KIA | AS8: Soluto | AT8: auto mediano B | AU8: 648 | AV8: =+AU8/$AU$391 -> 0.026947228
A9: AION | B9: YPLUS | C9: SUV mediano C | D9: 0 | E9: 6 | F9: 0 | G9: 9 | H9: 0 | I9: 0 | J9: 0 | K9: 0 | L9: 0 | M9: 0 | N9: 0 | O9: 0 | P9: =SUM(D9:O9) -> 15 | Q9: =+P9/$P$766 -> 0.00062377843 | R9: - | S9: - | AQ9: Kia Sonet | AR9: KIA | AS9: Sonet | AT9: SUV Mediano B | AU9: 528 | AV9: =+AU9/$AU$391 -> 0.021957001
A10: ARCFOX | B10: S5 | C10: Auto grande D | D10: 0 | E10: 0 | F10: 0 | G10: 0 | H10: 1 | I10: 0 | J10: 0 | K10: 0 | L10: 0 | M10: 0 | N10: 0 | O10: 0 | P10: =SUM(D10:O10) -> 1 | Q10: =+P10/$P$766 -> 4.1585229e-05 | AQ10: Kia Sportage | AR10: KIA | AS10: Sportage | AT10: SUV mediano C | AU10: 508 | AV10: =+AU10/$AU$391 -> 0.021125296
A11: ARCFOX | B11: T5 | C11: SUV mediano B | D11: 0 | E11: 0 | F11: 0 | G11: 0 | H11: 1 | I11: 0 | J11: 0 | K11: 0 | L11: 0 | M11: 0 | N11: 0 | O11: 0 | P11: =SUM(D11:O11) -> 1 | Q11: =+P11/$P$766 -> 4.1585229e-05 | AQ11: Hyundai HB20 | AR11: HYUNDAI | AS11: HB20 | AT11: auto mediano B | AU11: 500 | AV11: =+AU11/$AU$391 -> 0.020792614
A12: AUDI | B12: A3 | C12: Auto mediano C | D12: 0 | E12: 0 | F12: 0 | G12: 1 | H12: 0 | I12: 0 | J12: 0 | K12: 0 | L12: 0 | M12: 0 | N12: 0 | O12: 0 | P12: =SUM(D12:O12) -> 1 | Q12: =+P12/$P$766 -> 4.1585229e-05 | R12: - | S12: - | AQ12: Suzuki Fronx | AR12: SUZUKI | AS12: Fronx | AT12: SUV mediano B | AU12: 500 | AV12: =+AU12/$AU$391 -> 0.020792614
A13: AUDI | B13: A4 | C13: Auto mediano C | D13: 1 | E13: 0 | F13: 0 | G13: 0 | H13: 0 | I13: 0 | J13: 0 | K13: 0 | L13: 0 | M13: 0 | N13: 0 | O13: 0 | P13: =SUM(D13:O13) -> 1 | Q13: =+P13/$P$766 -> 4.1585229e-05 | R13: - | S13: - | AQ13: Fiat Pulse | AR13: FIAT | AS13: Pulse | AT13: SUV mediano B | AU13: 488 | AV13: =+AU13/$AU$391 -> 0.020293592
A14: AUDI | B14: A5 | C14: Auto mediano C | D14: 0 | E14: 0 | F14: 1 | G14: 0 | H14: 0 | I14: 0 | J14: 0 | K14: 0 | L14: 0 | M14: 0 | N14: 0 | O14: 0 | P14: =SUM(D14:O14) -> 1 | Q14: =+P14/$P$766 -> 4.1585229e-05 | R14: - | S14: - | AQ14: Toyota Corolla Cross | AR14: TOYOTA | AS14: Corolla Cross | AT14: SUV mediano C | AU14: 441 | AV14: =+AU14/$AU$391 -> 0.018339086
A15: AUDI | B15: A6 | C15: Auto grande E | D15: 0 | E15: 0 | F15: 0 | G15: 0 | H15: 0 | I15: 0 | J15: 0 | K15: 0 | L15: 0 | M15: 0 | N15: 0 | O15: 0 | P15: =SUM(D15:O15) -> 0 | Q15: =+P15/$P$766 -> 0 | R15: - | S15: - | AQ15: MG ZS | AR15: MG | AS15: ZS | AT15: SUV grande D | AU15: 430 | AV15: =+AU15/$AU$391 -> 0.017881648
A16: AUDI | B16: A8 | C16: Auto grande F | D16: 1 | E16: 0 | F16: 0 | G16: 0 | H16: 0 | I16: 0 | J16: 0 | K16: 0 | L16: 0 | M16: 0 | N16: 0 | O16: 0 | P16: =SUM(D16:O16) -> 1 | Q16: =+P16/$P$766 -> 4.1585229e-05 | R16: - | S16: - | AQ16: Vw Saveiro | AR16: VW | AS16: Saveiro | AT16: Pick up pequeño | AU16: 408 | AV16: =+AU16/$AU$391 -> 0.016966773
A17: AUDI | B17: E5 | C17: Auto deportivo | D17: 0 | E17: 0 | F17: 2 | G17: 0 | H17: 0 | I17: 0 | J17: 0 | K17: 0 | L17: 0 | M17: 0 | N17: 0 | O17: 0 | P17: =SUM(D17:O17) -> 2 | Q17: =+P17/$P$766 -> 8.3170458e-05 | AQ17: Chevrolet Tracker | AR17: CHEVROLET | AS17: Tracker | AT17: SUV mediano B | AU17: 378 | AV17: =+AU17/$AU$391 -> 0.015719217
A18: AUDI | B18: E TRON GT RS | C18: Auto deportivo | D18: 0 | E18: 0 | F18: 0 | G18: 0 | H18: 0 | I18: 0 | J18: 0 | K18: 0 | L18: 0 | M18: 0 | N18: 0 | O18: 0 | P18: =SUM(D18:O18) -> 0 | Q18: =+P18/$P$766 -> 0 | R18: - | S18: - | AQ18: Chevrolet Onix | AR18: CHEVROLET | AS18: Onix | AT18: Auto mediano B | AU18: 364 | AV18: =+AU18/$AU$391 -> 0.015137023
A19: AUDI | B19: E-tron | C19: SUV grande D | D19: 0 | E19: 0 | F19: 0 | G19: 0 | H19: 0 | I19: 0 | J19: 0 | K19: 0 | L19: 0 | M19: 0 | N19: 0 | O19: 0 | P19: =SUM(D19:O19) -> 0 | Q19: =+P19/$P$766 -> 0 | R19: - | S19: - | AQ19: Geely Coolray | AR19: GEELY | AS19: Coolray | AT19: SUV mediano c | AU19: 353 | AV19: =+AU19/$AU$391 -> 0.014679586
A20: AUDI | B20: ETRON 50 | C20: SUV mediano C | D20: 0 | E20: 0 | F20: 0 | G20: 0 | H20: 0 | I20: 0 | J20: 0 | K20: 0 | L20: 0 | M20: 0 | N20: 0 | O20: 0 | P20: =SUM(D20:O20) -> 0 | Q20: =+P20/$P$766 -> 0 | R20: - | S20: - | AQ20: Nissan Kicks | AR20: NISSAN | AS20: Kicks | AT20: suv mediano B | AU20: 346 | AV20: =+AU20/$AU$391 -> 0.014388489
A21: AUDI | B21: ETRON 55 | C21: SUV mediano C | D21: 0 | E21: 0 | F21: 0 | G21: 0 | H21: 0 | I21: 0 | J21: 0 | K21: 0 | L21: 0 | M21: 0 | N21: 0 | O21: 0 | P21: =SUM(D21:O21) -> 0 | Q21: =+P21/$P$766 -> 0 | R21: - | S21: - | AQ21: Vw TERA | AR21: VW | AS21: TERA | AT21: SUV mediano B | AU21: 338 | AV21: =+AU21/$AU$391 -> 0.014055807
A22: AUDI | B22: ETRON GT RS | C22: Auto deportivo | D22: 0 | E22: 0 | F22: 0 | G22: 0 | H22: 0 | I22: 0 | J22: 0 | K22: 0 | L22: 0 | M22: 0 | N22: 0 | O22: 0 | P22: =SUM(D22:O22) -> 0 | Q22: =+P22/$P$766 -> 0 | R22: - | S22: - | AQ22: Fiat Fiorino | AR22: FIAT | AS22: Fiorino | AT22: Furgon Pequeño | AU22: 337 | AV22: =+AU22/$AU$391 -> 0.014014222
A23: AUDI | B23: Q2 | C23: SUV mediano C | D23: 1 | E23: 4 | F23: 0 | G23: 0 | H23: 3 | I23: 0 | J23: 0 | K23: 0 | L23: 0 | M23: 0 | N23: 0 | O23: 0 | P23: =SUM(D23:O23) -> 8 | Q23: =+P23/$P$766 -> 0.00033268183 | R23: - | S23: - | AQ23: Vw T-Cross | AR23: VW | AS23: T-Cross | AT23: SUV mediano B | AU23: 336 | AV23: =+AU23/$AU$391 -> 0.013972637
A24: AUDI | B24: Q3 | C24: SUV mediano C | D24: 0 | E24: 1 | F24: 12 | G24: 5 | H24: 2 | I24: 4 | J24: 0 | K24: 0 | L24: 0 | M24: 0 | N24: 0 | O24: 0 | P24: =SUM(D24:O24) -> 24 | Q24: =+P24/$P$766 -> 0.00099804549 | R24: - | S24: - | AQ24: Suzuki Jimny | AR24: SUZUKI | AS24: Jimny | AT24: SUV mediano B | AU24: 319 | AV24: =+AU24/$AU$391 -> 0.013265688
A25: AUDI | B25: Q4 | C25: SUV mediano C | D25: 1 | E25: 0 | F25: 1 | G25: 0 | H25: 0 | I25: 0 | J25: 0 | K25: 0 | L25: 0 | M25: 0 | N25: 0 | O25: 0 | P25: =SUM(D25:O25) -> 2 | Q25: =+P25/$P$766 -> 8.3170458e-05 | R25: - | S25: - | AR25: HYUNDAI | AS25: HB20S | AT25: auto mediano B | AU25: 310 | AV25: =+AU25/$AU$391 -> 0.012891421
A26: AUDI | B26: Q5 | C26: SUV mediano D | D26: 11 | E26: 9 | F26: 2 | G26: 1 | H26: 3 | I26: 1 | J26: 0 | K26: 0 | L26: 0 | M26: 0 | N26: 0 | O26: 0 | P26: =SUM(D26:O26) -> 27 | Q26: =+P26/$P$766 -> 0.0011228012 | R26: 46000 | S26: 35226.65 | AR26: GEELY | AS26: Emgrand | AT26: SUV grande D | AU26: 293 | AV26: =+AU26/$AU$391 -> 0.012184472
A27: AUDI | B27: Q6 | C27: SUV mediano D | D27: 0 | E27: 4 | F27: 0 | G27: 0 | H27: 3 | I27: 2 | J27: 0 | K27: 0 | L27: 0 | M27: 0 | N27: 0 | O27: 0 | P27: =SUM(D27:O27) -> 9 | Q27: =+P27/$P$766 -> 0.00037426706 | R27: - | S27: - | AR27: SUZUKI | AS27: VITARA ACROSS | AT27: SUV mediano B | AU27: 280 | AV27: =+AU27/$AU$391 -> 0.011643864
A28: AUDI | B28: Q7 | C28: SUV grande F | D28: 0 | E28: 2 | F28: 1 | G28: 3 | H28: 1 | I28: 2 | J28: 0 | K28: 0 | L28: 0 | M28: 0 | N28: 0 | O28: 0 | P28: =SUM(D28:O28) -> 9 | Q28: =+P28/$P$766 -> 0.00037426706 | R28: - | S28: - | AR28: TOYOTA | AS28: Yaris Cross | AT28: Auto mediano B | AU28: 276 | AV28: =+AU28/$AU$391 -> 0.011477523
A29: AUDI | B29: Q7 E-tron | C29: SUV grande D | D29: 0 | E29: 0 | F29: 0 | G29: 0 | H29: 0 | I29: 0 | J29: 0 | K29: 0 | L29: 0 | M29: 0 | N29: 0 | O29: 0 | P29: =SUM(D29:O29) -> 0 | Q29: =+P29/$P$766 -> 0 | R29: - | S29: - | AR29: HYUNDAI | AS29: Tucson | AT29: SUV mediano C | AU29: 269 | AV29: =+AU29/$AU$391 -> 0.011186427
A30: AUDI | B30: Q8 | C30: SUV grande F | D30: 5 | E30: 0 | F30: 0 | G30: 2 | H30: 1 | I30: 2 | J30: 0 | K30: 0 | L30: 0 | M30: 0 | N30: 0 | O30: 0 | P30: =SUM(D30:O30) -> 10 | Q30: =+P30/$P$766 -> 0.00041585229 | R30: 79181.86 | S30: 74230.69 | AR30: TOYOTA | AS30: Fortuner | AT30: SUV Grande D | AU30: 266 | AV30: =+AU30/$AU$391 -> 0.011061671
A31: AUDI | B31: Q8 ETRON | C31: SUV grande F | D31: 0 | E31: 0 | F31: 0 | G31: 0 | H31: 0 | I31: 0 | J31: 0 | K31: 0 | L31: 0 | M31: 0 | N31: 0 | O31: 0 | P31: =SUM(D31:O31) -> 0 | Q31: =+P31/$P$766 -> 0 | R31: - | S31: - | AR31: TOYOTA | AS31: Raize | AT31: SUV mediano B | AU31: 260 | AV31: =+AU31/$AU$391 -> 0.01081216
A32: AUDI | B32: R8 | C32: Auto deportivo | D32: 0 | E32: 0 | F32: 0 | G32: 0 | H32: 0 | I32: 0 | J32: 0 | K32: 0 | L32: 0 | M32: 0 | N32: 0 | O32: 0 | P32: =SUM(D32:O32) -> 0 | Q32: =+P32/$P$766 -> 0 | R32: - | S32: - | AR32: JEEP | AS32: Compass | AT32: SUV mediano C | AU32: 252 | AV32: =+AU32/$AU$391 -> 0.010479478
A33: AUDI | B33: RS6 | C33: Auto grande E | D33: 1 | E33: 0 | F33: 0 | G33: 1 | H33: 0 | I33: 0 | J33: 0 | K33: 0 | L33: 0 | M33: 0 | N33: 0 | O33: 0 | P33: =SUM(D33:O33) -> 2 | Q33: =+P33/$P$766 -> 8.3170458e-05 | R33: - | S33: - | AR33: ISUZU | AS33: D-MAX | AT33: Pick up mediano | AU33: 251 | AV33: =+AU33/$AU$391 -> 0.010437892
A34: AUDI | B34: RS Q3 | C34: SUV mediano C | D34: 0 | E34: 0 | F34: 0 | G34: 0 | H34: 0 | I34: 0 | J34: 0 | K34: 0 | L34: 0 | M34: 0 | N34: 0 | O34: 0 | P34: =SUM(D34:O34) -> 0 | Q34: =+P34/$P$766 -> 0 | R34: - | S34: - | AR34: KIA | AS34: Seltos | AT34: SUV Mediano B | AU34: 244 | AV34: =+AU34/$AU$391 -> 0.010146796
A35: AUDI | B35: RSQ8 | C35: SUV mediano C | D35: 0 | E35: 0 | F35: 0 | G35: 0 | H35: 0 | I35: 0 | J35: 0 | K35: 0 | L35: 0 | M35: 0 | N35: 0 | O35: 0 | P35: =SUM(D35:O35) -> 0 | Q35: =+P35/$P$766 -> 0 | R35: - | S35: - | AR35: NISSAN | AS35: KAIT | AT35: suv mediano B | AU35: 244 | AV35: =+AU35/$AU$391 -> 0.010146796
A36: AUDI | B36: SQ5 | C36: SUV mediano C | D36: 0 | E36: 0 | F36: 0 | G36: 1 | H36: 0 | I36: 0 | J36: 0 | K36: 0 | L36: 0 | M36: 0 | N36: 0 | O36: 0 | P36: =SUM(D36:O36) -> 1 | Q36: =+P36/$P$766 -> 4.1585229e-05 | R36: - | S36: - | AR36: CHERY | AS36: T7 | AT36: SUV mediano B | AU36: 243 | AV36: =+AU36/$AU$391 -> 0.010105211
A37: AVATR | B37: AVATR 11 | C37: SUV grande E | D37: 0 | E37: 0 | F37: 10 | G37: 0 | H37: 0 | I37: 0 | J37: 0 | K37: 0 | L37: 0 | M37: 0 | N37: 0 | O37: 0 | P37: =SUM(D37:O37) -> 10 | Q37: =+P37/$P$766 -> 0.00041585229 | AR37: CHERY | AS37: T4 | AT37: SUV mediano C | AU37: 234 | AV37: =+AU37/$AU$391 -> 0.0097309436
A38: AVATR | B38: 07 | C38: SUV mediano C | D38: 0 | E38: 0 | F38: 0 | G38: 7 | H38: 0 | I38: 4 | J38: 0 | K38: 0 | L38: 0 | M38: 0 | N38: 0 | O38: 0 | P38: =SUM(D38:O38) -> 11 | Q38: =+P38/$P$766 -> 0.00045743752 | AR38: HYUNDAI | AS38: NEW GRAND I10 | AT38: auto mediano B | AU38: 231 | AV38: =+AU38/$AU$391 -> 0.0096061879
A39: BAIC | B39: BJ30 | C39: SUV mediano C | D39: 0 | E39: 13 | F39: 4 | G39: 0 | H39: 0 | I39: 14 | J39: 0 | K39: 0 | L39: 0 | M39: 0 | N39: 0 | O39: 0 | P39: =SUM(D39:O39) -> 31 | Q39: =+P39/$P$766 -> 0.0012891421 | R39: - | S39: - | AR39: CHEVROLET | AS39: Montana | AT39: Pick up pequeño | AU39: 205 | AV39: =+AU39/$AU$391 -> 0.0085249719
A40: BAIC | B40: BJ40 | C40: SUV mediano C | D40: 0 | E40: 0 | F40: 0 | G40: 0 | H40: 0 | I40: 0 | J40: 0 | K40: 0 | L40: 0 | M40: 0 | N40: 0 | O40: 0 | P40: =SUM(D40:O40) -> 0 | Q40: =+P40/$P$766 -> 0 | R40: - | S40: - | AQ40: Toyota RAV4 | AR40: NISSAN | AS40: Frontier | AT40: Pick up mediano | AU40: 200 | AV40: =+AU40/$AU$391 -> 0.0083170458
...

Sheet 9
V1: Referencias
A2: Cuadro 9: Importación de vehículos por tipo, 2026 | V2: Segmento | W2: Modelos. Ejemplos | X2: Capacidad de carga o pasajeros | Y2: Dimensiones
A3: Tipo | B3: Ene | C3: Feb | D3: Mar | E3: Abr | F3: May | G3: Jun | H3: Jul | I3: Ago | J3: Sep | K3: Oct | L3: Nov | M3: Dic | N3: Total | O3: En % | V3: Auto deportivo | W3: Challenger, mustang, slk 200, slk 350 | X3: 2 pasajeros
A4: SUV mediano B | B4: 888 | C4: 953 | D4: 1011 | E4: 1209 | F4: 1139 | G4: 1329 | L4: 0 | M4: 0 | N4: =SUM(B4:M4) -> 6529 | O4: =+N4/$N$26 -> 0.27150996 | V4: Auto Familiar | W4: peugeot 3008, citroen c8 | X4: 7 adultos | Y4: 4,85 mts
A5: SUV mediano C | B5: 864 | C5: 923 | D5: 986 | E5: 1017 | F5: 1018 | G5: 953 | L5: 0 | M5: 0 | N5: =SUM(B5:M5) -> 5761 | O5: =+N5/$N$26 -> 0.2395725 | V5: Auto grande D | W5: kia optima, | X5: 5 adultos | Y5: 4,85 mts
A6: Pick up mediano | B6: 327 | C6: 440 | D6: 624 | E6: 722 | F6: 826 | G6: 408 | L6: 0 | M6: 0 | N6: =SUM(B6:M6) -> 3347 | O6: =+N6/$N$26 -> 0.13918576 | V6: Auto grande F (lujo) | W6: audi A8 BMW serie 7 | Y6: 5 mts
A7: Auto mediano B | B7: 456 | C7: 386 | D7: 425 | E7: 487 | F7: 543 | G7: 723 | L7: 0 | M7: 0 | N7: =SUM(B7:M7) -> 3020 | O7: =+N7/$N$26 -> 0.12558739 | V7: Auto mediano B | W7: Fiat palio, VW gol, Chevrolet Onix, Kia Rio | X7: 4 adultos 1 niño | Y7: 3,75 mts
A8: Pick up pequeño | B8: 177 | C8: 143 | D8: 270 | E8: 517 | F8: 315 | G8: 260 | L8: 0 | M8: 0 | N8: =SUM(B8:M8) -> 1682 | O8: =+N8/$N$26 -> 0.069946355 | V8: Auto mediano C | W8: Toyota corolla, nissan sentra | X8: 5 adultos 2 niño | Y8: 4,30 a 4,50 mts
A9: SUV grande D | B9: 111 | C9: 137 | D9: 297 | E9: 244 | F9: 182 | G9: 252 | L9: 0 | M9: 0 | N9: =SUM(B9:M9) -> 1223 | O9: =+N9/$N$26 -> 0.050858735 | V9: Auto mediano D | W9: Audi a4, citroen c5 | X9: 5 adultos | Y9: 4,85 mts
A10: SUV grande E | B10: 138 | C10: 139 | D10: 208 | E10: 135 | F10: 171 | G10: 252 | L10: 0 | M10: 0 | N10: =SUM(B10:M10) -> 1043 | O10: =+N10/$N$26 -> 0.043373394 | V10: Auto mediano E | W10: Mercedes E500 | X10: 5 adultos | Y10: 4,95 mts
A11: Furgon pequeño | B11: 55 | C11: 40 | D11: 23 | E11: 123 | F11: 20 | G11: 115 | L11: 0 | M11: 0 | N11: =SUM(B11:M11) -> 376 | O11: =+N11/$N$26 -> 0.015636046 | V11: City car | W11: Suzuki celerio, chevrolet spark, Hyundai I10, Kia Picanto | X11: 4 adultos | Y11: 3mts
A12: Pick up grande | B12: 54 | C12: 43 | D12: 45 | E12: 67 | F12: 17 | G12: 65 | L12: 0 | M12: 0 | N12: =SUM(B12:M12) -> 291 | O12: =+N12/$N$26 -> 0.012101302 | V12: Auto pequeño | X12: 4 adultos | Y12: 3,56 mts
A13: SUV mediano D | B13: 30 | C13: 57 | D13: 31 | E13: 40 | F13: 27 | G13: 24 | L13: 0 | M13: 0 | N13: =SUM(B13:M13) -> 209 | O13: =+N13/$N$26 -> 0.0086913128 | V13: Furgon Grande | W13: Ford e350, Renault master, sprinter | X13: 3800 kg | Y13: 5,50 mts
A14: Auto mediano C | B14: 18 | C14: 9 | D14: 12 | E14: 11 | F14: 14 | G14: 84 | L14: 0 | M14: 0 | N14: =SUM(B14:M14) -> 148 | O14: =+N14/$N$26 -> 0.0061546139 | V14: Furgon mediano | W14: Citroen Berlingo | X14: 620 kg | Y14: 4,30mts
A15: City car | B15: 3 | C15: 5 | D15: 36 | E15: 17 | F15: 33 | G15: 27 | L15: 0 | M15: 0 | N15: =SUM(B15:M15) -> 121 | O15: =+N15/$N$26 -> 0.0050318127 | V15: Furgon Pequeño | W15: Renault Kangoo | X15: 550 kg | Y15: 4 mts
A16: Minibus | B16: 5 | C16: 28 | D16: 14 | E16: 15 | F16: 12 | G16: 6 | L16: 0 | M16: 0 | N16: =SUM(B16:M16) -> 80 | O16: =+N16/$N$26 -> 0.0033268183 | V16: Minibus | W16: Mercedes Sprinter | X16: 20 pasajeros
A17: Furgon Grande | B17: 20 | C17: 6 | D17: 20 | E17: 5 | F17: 12 | G17: 9 | L17: 0 | M17: 0 | N17: =SUM(B17:M17) -> 72 | O17: =+N17/$N$26 -> 0.0029941365 | V17: Pick up grande | W17: Dodge Ram, Ford F150, Toyota Tundra | X17: de 1000 a 3500 kg
A18: SUV grande F | B18: 21 | C18: 5 | D18: 12 | E18: 5 | F18: 8 | G18: 8 | L18: 0 | M18: 0 | N18: =SUM(B18:M18) -> 59 | O18: =+N18/$N$26 -> 0.0024535285 | V18: Pick up mediano | W18: Toyota Hilux. Nissan Frontier, Isuzu D-MAX | X18: 1,5 toneladas
